Workbook

Sheet Cover
B9: Tesla
B10: Company analysis

Sheet Drivers
B1: Drivers
B3: ="Selected Case:"&CHOOSE(C3," Best Case", " Base Case", " Worst Case") -> Selected Case: Best Case | C3: 1
B4: Company | C4: Tesla, Inc.
B5: Currency | C5: USD
B6: Domestic country | C6: United States
B7: 10-year treasury yield (Nov 7 2025) | C7: 0.04089
B8: Market risk premium US | C8: 0.05
B9: Company beta (Nov 7 2025) | C9: 1.87
B10: Tesla share price (Nov 7 2025) | C10: 433.33
B11: Bond Yield (Nov 7 2025) | C11: 0.053
B12: Corporate tax rate | C12: 0.21
B13: Expected inflation | C13: 0.02

Sheet Input -->
B14: Input -->

Sheet P&L Input
B1: P&L Input
B3: (in thousands) | C3: 2020 Act | D3: 2021 Act | E3: 2022 Act | F3: 2023 Act | G3: 2024 Act
B4: Automotive revenues | C4: 27236000 | D4: 47232000 | E4: 71462000 | F4: 82419000 | G4: 77070000
B5: Energy generation and storage | C5: 1994000 | D5: 2789000 | E5: 3909000 | F5: 6035000 | G5: 10086000
B6: Services and other | C6: 2306000 | D6: 3802000 | E6: 6091000 | F6: 8319000 | G6: 10534000
B7: Total revenues | C7: =SUM(C4:C6) -> 31536000 | D7: =SUM(D4:D6) -> 53823000 | E7: =SUM(E4:E6) -> 81462000 | F7: =SUM(F4:F6) -> 96773000 | G7: =SUM(G4:G6) -> 97690000
B8: Automotive cost of revenues | C8: -20259000 | D8: -33393000 | E8: -51108000 | F8: -66389000 | G8: -62873000
B9: Energy generation and storage cost of revenues | C9: -1976000 | D9: -2918000 | E9: -3621000 | F9: -4894000 | G9: -7446000
B10: Services and other cost of revenues | C10: -2671000 | D10: -3906000 | E10: -5880000 | F10: -7830000 | G10: -9921000
B11: Gross profit | C11: =SUM(C7:C10) -> 6630000 | D11: =SUM(D7:D10) -> 13606000 | E11: =SUM(E7:E10) -> 20853000 | F11: =SUM(F7:F10) -> 17660000 | G11: =SUM(G7:G10) -> 17450000
B12: Research and development | C12: -1491000 | D12: -2593000 | E12: -3075000 | F12: -3969000 | G12: -4540000
B13: Selling, general and administrative | C13: -3145000 | D13: -4517000 | E13: -3946000 | F13: -4800000 | G13: -5150000
B14: Restructuring and other | C14: - | D14: 27000 | E14: -176000 | F14: - | G14: -684000
B15: EBIT | C15: =SUM(C11:C14) -> 1994000 | D15: =SUM(D11:D14) -> 6523000 | E15: =SUM(E11:E14) -> 13656000 | F15: =SUM(F11:F14) -> 8891000 | G15: =SUM(G11:G14) -> 7076000
B16: Interest income | C16: 30000 | D16: 56000 | E16: 297000 | F16: 1066000 | G16: 1569000
B17: Interest expense | C17: -748000 | D17: -371000 | E17: -191000 | F17: -156000 | G17: -350000
B18: Other income (expense), net | C18: -122000 | D18: 135000 | E18: -43000 | F18: 172000 | G18: 695000
B19: EBT | C19: =SUM(C15:C18) -> 1154000 | D19: =SUM(D15:D18) -> 6343000 | E19: =SUM(E15:E18) -> 13719000 | F19: =SUM(F15:F18) -> 9973000 | G19: =SUM(G15:G18) -> 8990000
B20: Provision for income taxes | C20: -292000 | D20: -699000 | E20: -1132000 | F20: 5001000 | G20: -1837000
B21: Net lncome incl. minority interests | C21: =SUM(C19:C20) -> 862000 | D21: =SUM(D19:D20) -> 5644000 | E21: =SUM(E19:E20) -> 12587000 | F21: =SUM(F19:F20) -> 14974000 | G21: =SUM(G19:G20) -> 7153000
B22: Minority interests | C22: -141000 | D22: -125000 | E22: -31000 | F22: 23000 | G22: -62000
B23: Net Income | C23: =SUM(C21:C22) -> 721000 | D23: =SUM(D21:D22) -> 5519000 | E23: =SUM(E21:E22) -> 12556000 | F23: =SUM(F21:F22) -> 14997000 | G23: =SUM(G21:G22) -> 7091000
B25: KPIs
B26: Revenue % automotive y-o-y | D26: =D4/C4-1 -> 0.73417536 | E26: =E4/D4-1 -> 0.51299966 | F26: =F4/E4-1 -> 0.15332624 | G26: =G4/F4-1 -> -0.064900084
B27: Revenue % generation y-o-y | D27: =D5/C5-1 -> 0.39869609 | E27: =E5/D5-1 -> 0.40157763 | F27: =F5/E5-1 -> 0.54387311 | G27: =G5/F5-1 -> 0.67125104
B28: Revenue % services y-o-y | D28: =D6/C6-1 -> 0.64874241 | E28: =E6/D6-1 -> 0.60205155 | F28: =F6/E6-1 -> 0.36578559 | G28: =G6/F6-1 -> 0.26625796
B29: GP% automotive | C29: =(C4+C8)/C4 -> 0.25616831 | D29: =(D4+D8)/D4 -> 0.29300051 | E29: =(E4+E8)/E4 -> 0.2848227 | F29: =(F4+F8)/F4 -> 0.19449399 | G29: =(G4+G8)/G4 -> 0.18420916
B30: GP% energy generation and automotive | C30: =(C5+C9)/C5 -> 0.0090270812 | D30: =(D5+D9)/D5 -> -0.046253137 | E30: =(E5+E9)/E5 -> 0.073676132 | F30: =(F5+F9)/F5 -> 0.18906379 | G30: =(G5+G9)/G5 -> 0.26174896
B31: GP% services and other | C31: =(C6+C10)/C6 -> -0.15828274 | D31: =(D6+D10)/D6 -> -0.027354024 | E31: =(E6+E10)/E6 -> 0.034641274 | F31: =(F6+F10)/F6 -> 0.058781103 | G31: =(G6+G10)/G6 -> 0.058192519
B32: Overall GP% | C32: =(SUM(C4:C6)+SUM(C8:C10))/SUM(C4:C6) -> 0.21023592 | D32: =(SUM(D4:D6)+SUM(D8:D10))/SUM(D4:D6) -> 0.25279156 | E32: =(SUM(E4:E6)+SUM(E8:E10))/SUM(E4:E6) -> 0.25598439 | F32: =(SUM(F4:F6)+SUM(F8:F10))/SUM(F4:F6) -> 0.18248892 | G32: =(SUM(G4:G6)+SUM(G8:G10))/SUM(G4:G6) -> 0.17862627
B33: EBIT % | C33: =C15/C7 -> 0.063229325 | D33: =D15/D7 -> 0.12119354 | E33: =E15/E7 -> 0.16763644 | F33: =F15/F7 -> 0.0918748 | G33: =G15/G7 -> 0.072433207
B34: Net Income% | C34: =C23/C7 -> 0.02286276 | D34: =D23/D7 -> 0.10253981 | E34: =E23/E7 -> 0.15413322 | F34: =F23/F7 -> 0.15497091 | G34: =G23/G7 -> 0.072586754
B35: ROA | C35: =C23/'Balance Sheet Input'!C19 -> 0.013826034 | D35: =D23/'Balance Sheet Input'!D19 -> 0.088828443 | E35: =E23/'Balance Sheet Input'!E19 -> 0.15249338 | F35: =F23/'Balance Sheet Input'!F19 -> 0.14066105 | G35: =G23/'Balance Sheet Input'!G19 -> 0.058089621
B36: ROE | C36: =C23/'Balance Sheet Input'!C33 -> 0.032440945 | D36: =D23/'Balance Sheet Input'!D33 -> 0.18281493 | E36: =E23/'Balance Sheet Input'!E33 -> 0.28086972 | F36: =F23/'Balance Sheet Input'!F33 -> 0.23943864 | G36: =G23/'Balance Sheet Input'!G33 -> 0.09725289

Sheet Balance Sheet Input
B1: Balance Sheet Input
B3: (in thousands) | C3: 31 Dec 2020 | D3: 31 Dec 2021 | E3: 31 Dec 2022 | F3: 31 Dec 2023 | G3: 31 Dec 2024
B4: Cash and cash equivalents | C4: 19384000 | D4: 17576000 | E4: 16253000 | F4: 16398000 | G4: 16139000
B5: Short-term investments | C5: 0 | D5: 131000 | E5: 5932000 | F5: 12696000 | G5: 20424000
B6: Accounts receivable, net | C6: 1886000 | D6: 1913000 | E6: 2952000 | F6: 3508000 | G6: 4418000
B7: Inventory | C7: 4101000 | D7: 5757000 | E7: 12839000 | F7: 13626000 | G7: 12017000
B8: Prepaid expenses and other current assets | C8: 1346000 | D8: 1723000 | E8: 2941000 | F8: 3388000 | G8: 5362000
B9: Total current assets | C9: =SUM(C4:C8) -> 26717000 | D9: =SUM(D4:D8) -> 27100000 | E9: =SUM(E4:E8) -> 40917000 | F9: =SUM(F4:F8) -> 49616000 | G9: =SUM(G4:G8) -> 58360000
B10: Operating lease vehicles, net | C10: 3091000 | D10: 4511000 | E10: 5035000 | F10: 5989000 | G10: 5581000
B11: Solar energy systems, leased and to be leased, net | C11: 5979000 | D11: 5765000 | E11: 5489000 | F11: 5229000 | G11: 4924000
B12: Property, plant and equipment, net | C12: 12747000 | D12: 18884000 | E12: 23548000 | F12: 29725000 | G12: 35836000
B13: Operating lease right-of-use assets | C13: 1558000 | D13: 2016000 | E13: 2563000 | F13: 4180000 | G13: 5160000
B14: Digital Assets, net | C14: 0 | D14: 1260000 | E14: 184000 | F14: 184000 | G14: 1076000
B15: Intangible assets, net | C15: 313000 | D15: 257000 | E15: 215000 | F15: 178000 | G15: 150000
B16: Goodwill | C16: 207000 | D16: 200000 | E16: 194000 | F16: 253000 | G16: 244000
B17: Deferred Tax assets | C17: - | D17: - | E17: - | F17: 6733000 | G17: 6524000
B18: Other assets | C18: 1536000 | D18: 2138000 | E18: 4193000 | F18: 4531000 | G18: 4215000
B19: Total assets | C19: =SUM(C9:C18) -> 52148000 | D19: =SUM(D9:D18) -> 62131000 | E19: =SUM(E9:E18) -> 82338000 | F19: =SUM(F9:F18) -> 106618000 | G19: =SUM(G9:G18) -> 122070000
B20: Accounts payable | C20: 6051000 | D20: 10025000 | E20: 15255000 | F20: 14431000 | G20: 12474000
B21: Accrued liabilities | C21: 3855000 | D21: 5719000 | E21: 7142000 | F21: 9080000 | G21: 10723000
B22: Deferred revenue | C22: 1458000 | D22: 1447000 | E22: 1747000 | F22: 2864000 | G22: 3168000
B23: Customer Deposits | C23: 752000 | D23: 925000 | E23: 1063000 | F23: - | G23: -
B24: Current portion of long-term debt and capital leases | C24: 2132000 | D24: 1589000 | E24: 1502000 | F24: 2373000 | G24: 2456000
B25: Total current liabilities | C25: =SUM(C20:C24) -> 14248000 | D25: =SUM(D20:D24) -> 19705000 | E25: =SUM(E20:E24) -> 26709000 | F25: =SUM(F20:F24) -> 28748000 | G25: =SUM(G20:G24) -> 28821000
B26: Long-term debt and capital leases, net of current
B27: portion | C27: 9556000 | D27: 5245000 | E27: 1597000 | F27: 2857000 | G27: 5757000
B28: Deferred Revenue, net of current portion | C28: 1284000 | D28: 2052000 | E28: 2804000 | F28: 3251000 | G28: 3317000
B29: Other liabilities | C29: 3330000 | D29: 3546000 | E29: 5330000 | F29: 8153000 | G29: 10495000
B30: Total liabilities | C30: =SUM(C25:C29) -> 28418000 | D30: =SUM(D25:D29) -> 30548000 | E30: =SUM(E25:E29) -> 36440000 | F30: =SUM(F25:F29) -> 43009000 | G30: =SUM(G25:G29) -> 48390000
B31: Redeemable non controlling interest in subsidaries | C31: 604000 | D31: 568000 | E31: 409000 | F31: 242000 | G31: 63000
B32: Convertible Senior Notes | C32: 51000 | D32: - | E32: - | F32: - | G32: -
B33: Total stockholders' equity | C33: 22225000 | D33: 30189000 | E33: 44704000 | F33: 62634000 | G33: 72913000
B34: Noncontrolling interests in subsidiaries | C34: 850000 | D34: 826000 | E34: 785000 | F34: 733000 | G34: 704000
B35: Total liabilities and equity | C35: =SUM(C30:C34) -> 52148000 | D35: =SUM(D30:D34) -> 62131000 | E35: =SUM(E30:E34) -> 82338000 | F35: =SUM(F30:F34) -> 106618000 | G35: =SUM(G30:G34) -> 122070000
B37: KPIs
B38: Liquidity ratios
B39: Quick ratio | C39: =(C4+C5+C6)/C25 -> 1.4928411 | D39: =(D4+D5+D6)/D25 -> 0.99568637 | E39: =(E4+E5+E6)/E25 -> 0.94114343 | F39: =(F4+F5+F6)/F25 -> 1.1340615 | G39: =(G4+G5+G6)/G25 -> 1.4219146
B40: Current ratio | C40: =(C4+C5)/C25 -> 1.3604716 | D40: =(D4+D5)/D25 -> 0.89860442 | E40: =(E4+E5)/E25 -> 0.83061889 | F40: =(F4+F5)/F25 -> 1.0120356 | G40: =(G4+G5)/G25 -> 1.2686236
B41: DSO | C41: =(C6/'P&L Input'!C7)*360 -> 21.52968 | D41: =(D6/'P&L Input'!D7)*360 -> 12.795273 | E41: =(E6/'P&L Input'!E7)*360 -> 13.045592 | F41: =(F6/'P&L Input'!F7)*360 -> 13.049921 | G41: =(G6/'P&L Input'!G7)*360 -> 16.280889
B42: DIO | C42: =-(C7/(SUM('P&L Input'!C8:C10))*360) -> 59.277283 | D42: =-(D7/(SUM('P&L Input'!D8:D10))*360) -> 51.533431 | E42: =-(E7/(SUM('P&L Input'!E8:E10))*360) -> 76.259961 | F42: =-(F7/(SUM('P&L Input'!F8:F10))*360) -> 62.004475 | G42: =-(G7/(SUM('P&L Input'!G8:G10))*360) -> 53.914756
...

Sheet Workings -->
B14: Workings -->

Sheet Income Statement items
B14: Income Statement items

Sheet Automotive
B14: Automotive

Sheet Deliveries
B1: Deliveries
C3: Tesla Deliveries
B4: Vehicle | C4: 2020 Act | D4: 2021 Act | E4: 2022 Act | F4: 2023 Act | G4: 2024 Act | H4: 2025 Fcst | I4: 2026 Fcst | J4: 2027 Fcst | K4: 2028 Fcst | L4: 2029 Fcst | M4: 2030 Fcst | N4: 2031 Fcst | O4: 2032 Fcst | P4: 2033 Fcst | Q4: 2034 Fcst
B5: Tesla Model 3 and Y | C5: 375754 | D5: 783964 | E5: 1146350 | F5: 1311736 | G5: 1199755 | H5: =G5*(1+H11) -> 1259742.8 | I5: =H5*(1+I11) -> 1322729.9 | J5: =I5*(1+J11) -> 1388866.4 | K5: =J5*(1+K11) -> 1458309.7 | L5: =K5*(1+L11) -> 1531225.2 | M5: =L5*(1+M11) -> 1607786.4 | N5: =M5*(1+N11) -> 1688175.8 | O5: =N5*(1+O11) -> 1772584.6 | ... Q5: =P5*(1+Q11) -> 1954274.5
B6: Tesla Model S, X and Others | C6: 57039 | D6: 24964 | E6: 60000 | F6: 75000 | G6: 85133 | H6: =G6*(1+H12) -> 89389.65 | I6: =H6*(1+I12) -> 93859.133 | J6: =I6*(1+J12) -> 98552.089 | K6: =J6*(1+K12) -> 103479.69 | L6: =K6*(1+L12) -> 108653.68 | M6: =L6*(1+M12) -> 114086.36 | N6: =M6*(1+N12) -> 119790.68 | O6: =N6*(1+O12) -> 125780.21 | ... Q6: =P6*(1+Q12) -> 138672.69
B7: Total | C7: =SUM(C5:C6) -> 432793 | D7: =SUM(D5:D6) -> 808928 | E7: =SUM(E5:E6) -> 1206350 | F7: =SUM(F5:F6) -> 1386736 | G7: =SUM(G5:G6) -> 1284888 | H7: =SUM(H5:H6) -> 1349132.4 | I7: =SUM(I5:I6) -> 1416589 | J7: =SUM(J5:J6) -> 1487418.5 | ... Q7: =SUM(Q5:Q6) -> 2092947.2
B9: y-o-y growth %
B11: Tesla Model 3 and Y | C11: n.a. | D11: =D5/C5-1 -> 1.0863757 | E11: =E5/D5-1 -> 0.46224827 | F11: =F5/E5-1 -> 0.14427182 | G11: =G5/F5-1 -> -0.08536855 | H11: 0.05 | I11: 0.05 | J11: 0.05 | K11: 0.05 | L11: 0.05 | M11: 0.05 | N11: 0.05 | O11: 0.05 | P11: 0.05 | Q11: 0.05
B12: Tesla Model S, X, and Others | C12: n.a. | D12: =D6/C6-1 -> -0.56233454 | E12: =E6/D6-1 -> 1.403461 | F12: =F6/E6-1 -> 0.25 | G12: =G6/F6-1 -> 0.13510667 | H12: 0.05 | I12: 0.05 | J12: 0.05 | K12: 0.05 | L12: 0.05 | M12: 0.05 | N12: 0.05 | O12: 0.05 | P12: 0.05 | Q12: 0.05
B16: Forecast Additional Info: | C16: 1) Tesla splits its total car production into only 2 groups i.e. Model 3/Y and Model S/X/Others
C17: 2) YoY growth rate assumed to be average car production market rate i.e. 5%

Sheet Deliveries comparables
B1: Deliveries comparables
B3: Comparables 2020-2024
B6: Vehicle Sales 2020-2024 - average | C6: Average
B7: GM | C7: 6100000
B8: Ford | C8: 4200000
B9: Fiat Chrysler | C9: 1300000
B10: BMW | C10: 2300000
B11: Volkswagen | C11: 9000000
B12: Average | C12: =SUM(C7:C11) -> 22900000
B16: Tesla Expected Deliveries
B17: 2025 | D17: =Deliveries!H7 -> 1349132.4
B18: 2029 | D18: =Deliveries!L7 -> 1639878.9
B19: 2034 | D19: =Deliveries!Q7 -> 2092947.2

Sheet Revenue automotive
B1: Revenue Automotive
C3: Tesla Revenue Automotive (in mln $)
B4: Vehicle | C4: 2020 Act | D4: 2021 Act | E4: 2022 Act | F4: 2023 Act | G4: 2024 Act | H4: 2025 Fcst | I4: 2026 Fcst | J4: 2027 Fcst | K4: 2028 Fcst | L4: 2029 Fcst | M4: 2030 Fcst | N4: 2031 Fcst | O4: 2032 Fcst | P4: 2033 Fcst | Q4: 2034 Fcst | R4: Average Price ($)
B5: Tesla Model 3 and Y | C5: =($R$5*Deliveries!C5)/1000000 -> 21417.978 | D5: =($R$5*Deliveries!D5)/1000000 -> 44685.948 | E5: =($R$5*Deliveries!E5)/1000000 -> 65341.95 | F5: =($R$5*Deliveries!F5)/1000000 -> 74768.952 | G5: =($R$5*Deliveries!G5)/1000000 -> 68386.035 | H5: =($R$5*Deliveries!H5*H10)/1000000 -> 73241.443 | I5: =($R$5*Deliveries!I5*I10)/1000000 -> 76903.516 | J5: =($R$5*Deliveries!J5*J10)/1000000 -> 80748.691 | K5: =($R$5*Deliveries!K5*K10)/1000000 -> 84786.126 | L5: =($R$5*Deliveries!L5*L10)/1000000 -> 89025.432 | M5: =($R$5*Deliveries!M5*M10)/1000000 -> 93476.704 | N5: =($R$5*Deliveries!N5*N10)/1000000 -> 98150.539 | O5: =($R$5*Deliveries!O5*O10)/1000000 -> 103058.07 | ... Q5: =($R$5*Deliveries!Q5*Q10)/1000000 -> 113621.52 | R5: 57000
B6: Tesla Model S, X, and others | C6: =($R$6*Deliveries!C6)/1000000 -> 5817.978 | D6: =($R$6*Deliveries!D6)/1000000 -> 2546.328 | E6: =($R$6*Deliveries!E6)/1000000 -> 6120 | F6: =($R$6*Deliveries!F6)/1000000 -> 7650 | G6: =($R$6*Deliveries!G6)/1000000 -> 8683.566 | H6: =($R$5*Deliveries!H6*H11)/1000000 -> 5197.1143 | I6: =($R$5*Deliveries!I6*I11)/1000000 -> 5456.97 | J6: =($R$5*Deliveries!J6*J11)/1000000 -> 5729.8185 | K6: =($R$5*Deliveries!K6*K11)/1000000 -> 6016.3094 | L6: =($R$5*Deliveries!L6*L11)/1000000 -> 6317.1249 | M6: =($R$5*Deliveries!M6*M11)/1000000 -> 6632.9811 | N6: =($R$5*Deliveries!N6*N11)/1000000 -> 6964.6302 | O6: =($R$5*Deliveries!O6*O11)/1000000 -> 7312.8617 | ... Q6: =($R$5*Deliveries!Q6*Q11)/1000000 -> 8062.43 | R6: 102000
B7: Total | C7: =SUM(C5:C6) -> 27235.956 | D7: =SUM(D5:D6) -> 47232.276 | E7: =SUM(E5:E6) -> 71461.95 | F7: =SUM(F5:F6) -> 82418.952 | G7: =SUM(G5:G6) -> 77069.601 | H7: =SUM(H5:H6) -> 78438.558 | I7: =SUM(I5:I6) -> 82360.486 | J7: =SUM(J5:J6) -> 86478.51 | ... Q7: =SUM(Q5:Q6) -> 121683.95
B9: Selected case
B10: Tesla Model 3 and Y | H10: =CHOOSE(Drivers!$C$3,'Revenue automotive'!H14,'Revenue automotive'!H18,'Revenue automotive'!H22) -> 1.02 | I10: =CHOOSE(Drivers!$C$3,'Revenue automotive'!I14,'Revenue automotive'!I18,'Revenue automotive'!I22) -> 1.02 | J10: =CHOOSE(Drivers!$C$3,'Revenue automotive'!J14,'Revenue automotive'!J18,'Revenue automotive'!J22) -> 1.02 | K10: =CHOOSE(Drivers!$C$3,'Revenue automotive'!K14,'Revenue automotive'!K18,'Revenue automotive'!K22) -> 1.02 | L10: =CHOOSE(Drivers!$C$3,'Revenue automotive'!L14,'Revenue automotive'!L18,'Revenue automotive'!L22) -> 1.02 | M10: =CHOOSE(Drivers!$C$3,'Revenue automotive'!M14,'Revenue automotive'!M18,'Revenue automotive'!M22) -> 1.02 | N10: =CHOOSE(Drivers!$C$3,'Revenue automotive'!N14,'Revenue automotive'!N18,'Revenue automotive'!N22) -> 1.02 | O10: =CHOOSE(Drivers!$C$3,'Revenue automotive'!O14,'Revenue automotive'!O18,'Revenue automotive'!O22) -> 1.02 | ... Q10: =CHOOSE(Drivers!$C$3,'Revenue automotive'!Q14,'Revenue automotive'!Q18,'Revenue automotive'!Q22) -> 1.02
B11: Tesla Model S, X, and others | H11: =CHOOSE(Drivers!$C$3,'Revenue automotive'!H15,'Revenue automotive'!H19,'Revenue automotive'!H23) -> 1.02 | I11: =CHOOSE(Drivers!$C$3,'Revenue automotive'!I15,'Revenue automotive'!I19,'Revenue automotive'!I23) -> 1.02 | J11: =CHOOSE(Drivers!$C$3,'Revenue automotive'!J15,'Revenue automotive'!J19,'Revenue automotive'!J23) -> 1.02 | K11: =CHOOSE(Drivers!$C$3,'Revenue automotive'!K15,'Revenue automotive'!K19,'Revenue automotive'!K23) -> 1.02 | L11: =CHOOSE(Drivers!$C$3,'Revenue automotive'!L15,'Revenue automotive'!L19,'Revenue automotive'!L23) -> 1.02 | M11: =CHOOSE(Drivers!$C$3,'Revenue automotive'!M15,'Revenue automotive'!M19,'Revenue automotive'!M23) -> 1.02 | N11: =CHOOSE(Drivers!$C$3,'Revenue automotive'!N15,'Revenue automotive'!N19,'Revenue automotive'!N23) -> 1.02 | O11: =CHOOSE(Drivers!$C$3,'Revenue automotive'!O15,'Revenue automotive'!O19,'Revenue automotive'!O23) -> 1.02 | ... Q11: =CHOOSE(Drivers!$C$3,'Revenue automotive'!Q15,'Revenue automotive'!Q19,'Revenue automotive'!Q23) -> 1.02
B13: Best case
B14: Tesla Model 3 and Y | H14: 1.02 | I14: 1.02 | J14: 1.02 | K14: 1.02 | L14: 1.02 | M14: 1.02 | N14: 1.02 | O14: 1.02 | P14: 1.02 | Q14: 1.02
B15: Tesla Model S, X, and others | H15: 1.02 | I15: 1.02 | J15: 1.02 | K15: 1.02 | L15: 1.02 | M15: 1.02 | N15: 1.02 | O15: 1.02 | P15: 1.02 | Q15: 1.02
B17: Base case
B18: Tesla Model 3 and Y | H18: 1 | I18: 1 | J18: 1 | K18: 1 | L18: 1 | M18: 1 | N18: 1 | O18: 1 | P18: 1 | Q18: 1
B19: Tesla Model S, X, and others | H19: 1 | I19: 1 | J19: 1 | K19: 1 | L19: 1 | M19: 1 | N19: 1 | O19: 1 | P19: 1 | Q19: 1
B21: Worst case
B22: Tesla Model 3 and Y | H22: 0.98 | I22: 0.98 | J22: 0.98 | K22: 0.98 | L22: 0.98 | M22: 0.98 | N22: 0.98 | O22: 0.98 | P22: 0.98 | Q22: 0.98
B23: Tesla Model S, X, and others | H23: 0.98 | I23: 0.98 | J23: 0.98 | K23: 0.98 | L23: 0.98 | M23: 0.98 | N23: 0.98 | O23: 0.98 | P23: 0.98 | Q23: 0.98

Sheet GP% automotive
B1: GP %
B3: Comparables 2024
B5: Vehicle | C5: Comparable companies | D5: GP % Comp. 1 | E5: GP % Comp. 2 | F5: GP % Comp. 3 | H5: Average
B6: Tesla Model 3 and Y | C6: GM, Ford, Fiat Chrysler | D6: 0.187 | E6: =(((155900-134693)/155900)+((160338-136269)/160338))/2 -> 0.14307182 | F6: =(((108187-93164)/108187)+((110412-95011)/110412))/2 -> 0.13917403 | H6: =C12 -> 0.18935157 | I6: Historic
B7: Tesla Model S, X, and Others | C7: BMW, Mercedes Cars, Volkswagen | D7: =((13620/91682)+(13928/85846))/2 -> 0.15540049 | E7: =((33067/167362)+(29165/172745))/2 -> 0.18320519 | F7: 0.172 | H7: =C13 -> 0.18935157 | I7: Historic
B9: Historical
B11: Vehicle | C11: Historic Average GP%
B12: Tesla Model 3 and Y | C12: =AVERAGE('P&L Input'!$F$29,'P&L Input'!$G$29) -> 0.18935157
B13: Tesla Model S, X, and others | C13: =AVERAGE('P&L Input'!$F$29,'P&L Input'!$G$29) -> 0.18935157

Sheet GP automotive
B1: Gross Profit
C3: Tesla Gross Profit (in mln $)
B4: Vehicle | C4: 2020 Act | D4: 2021 Act | E4: 2022 Act | F4: 2023 Act | G4: 2024 Act | H4: 2025 Fcst | I4: 2026 Fcst | J4: 2027 Fcst | K4: 2028 Fcst | L4: 2029 Fcst | M4: 2030 Fcst | N4: 2031 Fcst | O4: 2032 Fcst | P4: 2033 Fcst | Q4: 2034 Fcst
B5: Tesla Model 3 and Y | C5: n.a. | D5: n.a. | E5: n.a. | F5: n.a. | G5: n.a. | H5: ='Revenue automotive'!H5*'GP automotive'!H10 -> 17431.464 | I5: ='Revenue automotive'!I5*'GP automotive'!I10 -> 18303.037 | J5: ='Revenue automotive'!J5*'GP automotive'!J10 -> 19218.189 | K5: ='Revenue automotive'!K5*'GP automotive'!K10 -> 20179.098 | L5: ='Revenue automotive'!L5*'GP automotive'!L10 -> 21188.053 | M5: ='Revenue automotive'!M5*'GP automotive'!M10 -> 22247.456 | N5: ='Revenue automotive'!N5*'GP automotive'!N10 -> 23359.828 | O5: ='Revenue automotive'!O5*'GP automotive'!O10 -> 24527.82 | ... Q5: ='Revenue automotive'!Q5*'GP automotive'!Q10 -> 27041.921
B6: Tesla Model S, X, and Others | C6: n.a. | D6: n.a. | E6: n.a. | F6: n.a. | G6: n.a. | H6: ='Revenue automotive'!H6*'GP automotive'!H11 -> 1236.9132 | I6: ='Revenue automotive'!I6*'GP automotive'!I11 -> 1298.7589 | J6: ='Revenue automotive'!J6*'GP automotive'!J11 -> 1363.6968 | K6: ='Revenue automotive'!K6*'GP automotive'!K11 -> 1431.8816 | L6: ='Revenue automotive'!L6*'GP automotive'!L11 -> 1503.4757 | M6: ='Revenue automotive'!M6*'GP automotive'!M11 -> 1578.6495 | N6: ='Revenue automotive'!N6*'GP automotive'!N11 -> 1657.582 | O6: ='Revenue automotive'!O6*'GP automotive'!O11 -> 1740.4611 | ... Q6: ='Revenue automotive'!Q6*'GP automotive'!Q11 -> 1918.8583
B7: Total | C7: ='P&L Input'!C11/1000 -> 6630 | D7: ='P&L Input'!D11/1000 -> 13606 | E7: ='P&L Input'!E11/1000 -> 20853 | F7: ='P&L Input'!F11/1000 -> 17660 | G7: ='P&L Input'!G11/1000 -> 17450 | H7: =SUM(H5:H6) -> 18668.377 | I7: =SUM(I5:I6) -> 19601.796 | J7: =SUM(J5:J6) -> 20581.885 | K7: =SUM(K5:K6) -> 21610.98 | L7: =SUM(L5:L6) -> 22691.529 | M7: =SUM(M5:M6) -> 23826.105 | N7: =SUM(N5:N6) -> 25017.41 | O7: =SUM(O5:O6) -> 26268.281 | ... Q7: =SUM(Q5:Q6) -> 28960.78
B9: Selected case
B10: Tesla Model 3 and Y | H10: =CHOOSE(Drivers!$C$3,'GP automotive'!H14,'GP automotive'!H18,'GP automotive'!H22) -> 0.238 | I10: =CHOOSE(Drivers!$C$3,'GP automotive'!I14,'GP automotive'!I18,'GP automotive'!I22) -> 0.238 | J10: =CHOOSE(Drivers!$C$3,'GP automotive'!J14,'GP automotive'!J18,'GP automotive'!J22) -> 0.238 | K10: =CHOOSE(Drivers!$C$3,'GP automotive'!K14,'GP automotive'!K18,'GP automotive'!K22) -> 0.238 | L10: =CHOOSE(Drivers!$C$3,'GP automotive'!L14,'GP automotive'!L18,'GP automotive'!L22) -> 0.238 | M10: =CHOOSE(Drivers!$C$3,'GP automotive'!M14,'GP automotive'!M18,'GP automotive'!M22) -> 0.238 | N10: =CHOOSE(Drivers!$C$3,'GP automotive'!N14,'GP automotive'!N18,'GP automotive'!N22) -> 0.238 | O10: =CHOOSE(Drivers!$C$3,'GP automotive'!O14,'GP automotive'!O18,'GP automotive'!O22) -> 0.238 | ... Q10: =CHOOSE(Drivers!$C$3,'GP automotive'!Q14,'GP automotive'!Q18,'GP automotive'!Q22) -> 0.238
B11: Tesla Model S, X, and Others | H11: =CHOOSE(Drivers!$C$3,'GP automotive'!H15,'GP automotive'!H19,'GP automotive'!H23) -> 0.238 | I11: =CHOOSE(Drivers!$C$3,'GP automotive'!I15,'GP automotive'!I19,'GP automotive'!I23) -> 0.238 | J11: =CHOOSE(Drivers!$C$3,'GP automotive'!J15,'GP automotive'!J19,'GP automotive'!J23) -> 0.238 | K11: =CHOOSE(Drivers!$C$3,'GP automotive'!K15,'GP automotive'!K19,'GP automotive'!K23) -> 0.238 | L11: =CHOOSE(Drivers!$C$3,'GP automotive'!L15,'GP automotive'!L19,'GP automotive'!L23) -> 0.238 | M11: =CHOOSE(Drivers!$C$3,'GP automotive'!M15,'GP automotive'!M19,'GP automotive'!M23) -> 0.238 | N11: =CHOOSE(Drivers!$C$3,'GP automotive'!N15,'GP automotive'!N19,'GP automotive'!N23) -> 0.238 | O11: =CHOOSE(Drivers!$C$3,'GP automotive'!O15,'GP automotive'!O19,'GP automotive'!O23) -> 0.238 | ... Q11: =CHOOSE(Drivers!$C$3,'GP automotive'!Q15,'GP automotive'!Q19,'GP automotive'!Q23) -> 0.238
B13: Best case
B14: Tesla Model 3 and Y | H14: 0.238 | I14: 0.238 | J14: 0.238 | K14: 0.238 | L14: 0.238 | M14: 0.238 | N14: 0.238 | O14: 0.238 | P14: 0.238 | Q14: 0.238
B15: Tesla Model S, X, and Others | H15: 0.238 | I15: 0.238 | J15: 0.238 | K15: 0.238 | L15: 0.238 | M15: 0.238 | N15: 0.238 | O15: 0.238 | P15: 0.238 | Q15: 0.238
B17: Base case
B18: Tesla Model 3 and Y | H18: ='GP% automotive'!$H$6 -> 0.18935157 | I18: ='GP% automotive'!$H$6 -> 0.18935157 | J18: ='GP% automotive'!$H$6 -> 0.18935157 | K18: ='GP% automotive'!$H$6 -> 0.18935157 | L18: ='GP% automotive'!$H$6 -> 0.18935157 | M18: ='GP% automotive'!$H$6 -> 0.18935157 | N18: ='GP% automotive'!$H$6 -> 0.18935157 | O18: ='GP% automotive'!$H$6 -> 0.18935157 | ... Q18: ='GP% automotive'!$H$6 -> 0.18935157
B19: Tesla Model S, X, and Others | H19: ='GP% automotive'!$H$6 -> 0.18935157 | I19: ='GP% automotive'!$H$6 -> 0.18935157 | J19: ='GP% automotive'!$H$6 -> 0.18935157 | K19: ='GP% automotive'!$H$6 -> 0.18935157 | L19: ='GP% automotive'!$H$6 -> 0.18935157 | M19: ='GP% automotive'!$H$6 -> 0.18935157 | N19: ='GP% automotive'!$H$6 -> 0.18935157 | O19: ='GP% automotive'!$H$6 -> 0.18935157 | ... Q19: ='GP% automotive'!$H$6 -> 0.18935157
B21: Worst case
B22: Tesla Model 3 and Y | H22: 0.208 | I22: 0.208 | J22: 0.208 | K22: 0.208 | L22: 0.208 | M22: 0.208 | N22: 0.208 | O22: 0.208 | P22: 0.208 | Q22: 0.208
B23: Tesla Model S, X, and Others | H23: 0.208 | I23: 0.208 | J23: 0.208 | K23: 0.208 | L23: 0.208 | M23: 0.208 | N23: 0.208 | O23: 0.208 | P23: 0.208 | Q23: 0.208

Sheet COGS Automative
B1: Cost of Sales Automotive
C3: Tesla Cost of Sales (in mln $)
B4: Vehicle | C4: 2020 Act | D4: 2021 Act | E4: 2022 Act | F4: 2023 Act | G4: 2024 Act | H4: 2025 Fcst | I4: 2026 Fcst | J4: 2027 Fcst | K4: 2028 Fcst | L4: 2029 Fcst | M4: 2030 Fcst | N4: 2031 Fcst | O4: 2032 Fcst | P4: 2033 Fcst | Q4: 2034 Fcst
B5: Tesla Model 3 and Y | C5: n.a. | D5: n.a. | E5: n.a. | F5: n.a. | G5: n.a. | H5: =-'Revenue automotive'!H5-'GP automotive'!H5 -> -90672.907 | I5: =-'Revenue automotive'!I5-'GP automotive'!I5 -> -95206.552 | J5: =-'Revenue automotive'!J5-'GP automotive'!J5 -> -99966.88 | K5: =-'Revenue automotive'!K5-'GP automotive'!K5 -> -104965.22 | L5: =-'Revenue automotive'!L5-'GP automotive'!L5 -> -110213.49 | M5: =-'Revenue automotive'!M5-'GP automotive'!M5 -> -115724.16 | N5: =-'Revenue automotive'!N5-'GP automotive'!N5 -> -121510.37 | O5: =-'Revenue automotive'!O5-'GP automotive'!O5 -> -127585.89 | ... Q5: =-'Revenue automotive'!Q5-'GP automotive'!Q5 -> -140663.44
B6: Tesla Model S, X, and Others | C6: n.a. | D6: n.a. | E6: n.a. | F6: n.a. | G6: n.a. | H6: =-'Revenue automotive'!H6-'GP automotive'!H6 -> -6434.0274 | I6: =-'Revenue automotive'!I6-'GP automotive'!I6 -> -6755.7288 | J6: =-'Revenue automotive'!J6-'GP automotive'!J6 -> -7093.5153 | K6: =-'Revenue automotive'!K6-'GP automotive'!K6 -> -7448.191 | L6: =-'Revenue automotive'!L6-'GP automotive'!L6 -> -7820.6006 | M6: =-'Revenue automotive'!M6-'GP automotive'!M6 -> -8211.6306 | N6: =-'Revenue automotive'!N6-'GP automotive'!N6 -> -8622.2121 | O6: =-'Revenue automotive'!O6-'GP automotive'!O6 -> -9053.3227 | ... Q6: =-'Revenue automotive'!Q6-'GP automotive'!Q6 -> -9981.2883
B7: Total | C7: ='P&L Input'!C8/1000 -> -20259 | D7: ='P&L Input'!D8/1000 -> -33393 | E7: ='P&L Input'!E8/1000 -> -51108 | F7: ='P&L Input'!F8/1000 -> -66389 | G7: ='P&L Input'!G8/1000 -> -62873 | H7: =SUM(H5:H6) -> -97106.934 | I7: =SUM(I5:I6) -> -101962.28 | J7: =SUM(J5:J6) -> -107060.4 | K7: =SUM(K5:K6) -> -112413.42 | L7: =SUM(L5:L6) -> -118034.09 | M7: =SUM(M5:M6) -> -123935.79 | N7: =SUM(N5:N6) -> -130132.58 | O7: =SUM(O5:O6) -> -136639.21 | ... Q7: =SUM(Q5:Q6) -> -150644.73

Sheet Revenue & GP autom
B1: Revenue and Gross Profit automotive
B3: Vehicle | C3: 2021 Act | D3: 2022 Act | E3: 2023 Act | F3: 2024 Act | G3: 2025 Fcst | H3: 2026 Fcst | I3: 2027 Fcst | J3: 2028 Fcst | K3: 2029 Fcst | L3: 2030 Fcst | M3: 2031 Fcst | N3: 2032 Fcst | O3: 2033 Fcst | P3: 2034 Fcst
B4: Revenue automotive | C4: ='P&L Input'!D4/1000 -> 47232 | D4: ='P&L Input'!E4/1000 -> 71462 | E4: ='P&L Input'!F4/1000 -> 82419 | F4: ='P&L Input'!G4/1000 -> 77070 | G4: ='Revenue automotive'!H7 -> 78438.558 | H4: ='Revenue automotive'!I7 -> 82360.486 | I4: ='Revenue automotive'!J7 -> 86478.51 | J4: ='Revenue automotive'!K7 -> 90802.435 | K4: ='Revenue automotive'!L7 -> 95342.557 | L4: ='Revenue automotive'!M7 -> 100109.69 | M4: ='Revenue automotive'!N7 -> 105115.17 | N4: ='Revenue automotive'!O7 -> 110370.93 | ... P4: ='Revenue automotive'!Q7 -> 121683.95
B5: Gross Profit automotive | C5: ='P&L Input'!D11/1000 -> 13606 | D5: ='P&L Input'!E11/1000 -> 20853 | E5: ='P&L Input'!F11/1000 -> 17660 | F5: ='P&L Input'!G11/1000 -> 17450 | G5: ='GP automotive'!H7 -> 18668.377 | H5: ='GP automotive'!I7 -> 19601.796 | I5: ='GP automotive'!J7 -> 20581.885 | J5: ='GP automotive'!K7 -> 21610.98 | K5: ='GP automotive'!L7 -> 22691.529 | L5: ='GP automotive'!M7 -> 23826.105 | M5: ='GP automotive'!N7 -> 25017.41 | N5: ='GP automotive'!O7 -> 26268.281 | ... P5: ='GP automotive'!Q7 -> 28960.78
B6: GP% | C6: =C5/C4 -> 0.28806741 | D6: =D5/D4 -> 0.29180544 | E6: =E5/E4 -> 0.21427098 | F6: =F5/F4 -> 0.22641754 | G6: =G5/G4 -> 0.238 | H6: =H5/H4 -> 0.238 | I6: =I5/I4 -> 0.238 | J6: =J5/J4 -> 0.238 | ... P6: =P5/P4 -> 0.238

Sheet Energy & Other
B14: Energy & Other

Sheet Revenue Energy & Other
B1: Revenue Energy & Other
C3: Tesla Revenue Energy & Other (in mln $)
B4: ($ in million) | C4: 2020 Act | D4: 2021 Act | E4: 2022 Act | F4: 2023 Act | G4: 2024 Act | H4: 2025 Fcst | I4: 2026 Fcst | J4: 2027 Fcst | K4: 2028 Fcst | L4: 2029 Fcst | M4: 2030 Fcst | N4: 2031 Fcst | O4: 2032 Fcst | P4: 2033 Fcst | Q4: 2034 Fcst
B5: Energy generation and storage | C5: ='P&L Input'!C5/1000 -> 1994 | D5: ='P&L Input'!D5/1000 -> 2789 | E5: ='P&L Input'!E5/1000 -> 3909 | F5: ='P&L Input'!F5/1000 -> 6035 | G5: ='P&L Input'!G5/1000 -> 10086 | H5: n.a. | I5: n.a. | J5: n.a. | K5: n.a. | L5: n.a. | M5: n.a. | N5: n.a. | O5: n.a. | P5: n.a. | Q5: n.a.
B6: Services and other | C6: ='P&L Input'!C6/1000 -> 2306 | D6: ='P&L Input'!D6/1000 -> 3802 | E6: ='P&L Input'!E6/1000 -> 6091 | F6: ='P&L Input'!F6/1000 -> 8319 | G6: ='P&L Input'!G6/1000 -> 10534 | H6: n.a. | I6: n.a. | J6: n.a. | K6: n.a. | L6: n.a. | M6: n.a. | N6: n.a. | O6: n.a. | P6: n.a. | Q6: n.a.
B7: Total Energy and Other | C7: =SUM(C5:C6) -> 4300 | D7: =SUM(D5:D6) -> 6591 | E7: =SUM(E5:E6) -> 10000 | F7: =SUM(F5:F6) -> 14354 | G7: =SUM(G5:G6) -> 20620 | H7: =G7*(1+H10) -> 29280.4 | I7: =H7*(1+I10) -> 38650.128 | J7: =I7*(1+J10) -> 47153.156 | K7: =J7*(1+K10) -> 51868.472 | L7: =K7*(1+L10) -> 57055.319 | M7: =L7*(1+M10) -> 62760.851 | N7: =M7*(1+N10) -> 69036.936 | O7: =N7*(1+O10) -> 75940.63 | ... Q7: =P7*(1+Q10) -> 91888.162
B9: Selected case
B10: Total Energy and Other | H10: =CHOOSE(Drivers!$C$3,'Revenue Energy & Other'!H14,'Revenue Energy & Other'!H17,'Revenue Energy & Other'!H20) -> 0.42 | I10: =CHOOSE(Drivers!$C$3,'Revenue Energy & Other'!I14,'Revenue Energy & Other'!I17,'Revenue Energy & Other'!I20) -> 0.32 | J10: =CHOOSE(Drivers!$C$3,'Revenue Energy & Other'!J14,'Revenue Energy & Other'!J17,'Revenue Energy & Other'!J20) -> 0.22 | K10: =CHOOSE(Drivers!$C$3,'Revenue Energy & Other'!K14,'Revenue Energy & Other'!K17,'Revenue Energy & Other'!K20) -> 0.1 | L10: =CHOOSE(Drivers!$C$3,'Revenue Energy & Other'!L14,'Revenue Energy & Other'!L17,'Revenue Energy & Other'!L20) -> 0.1 | M10: =CHOOSE(Drivers!$C$3,'Revenue Energy & Other'!M14,'Revenue Energy & Other'!M17,'Revenue Energy & Other'!M20) -> 0.1 | N10: =CHOOSE(Drivers!$C$3,'Revenue Energy & Other'!N14,'Revenue Energy & Other'!N17,'Revenue Energy & Other'!N20) -> 0.1 | O10: =CHOOSE(Drivers!$C$3,'Revenue Energy & Other'!O14,'Revenue Energy & Other'!O17,'Revenue Energy & Other'!O20) -> 0.1 | ... Q10: =CHOOSE(Drivers!$C$3,'Revenue Energy & Other'!Q14,'Revenue Energy & Other'!Q17,'Revenue Energy & Other'!Q20) -> 0.1
B12: Y-o-Y %
B13: Best case
B14: Total Energy and Other | H14: =H17+0.02 -> 0.42 | I14: =I17+0.02 -> 0.32 | J14: =J17+0.02 -> 0.22 | K14: =K17+0.02 -> 0.1 | L14: =L17+0.02 -> 0.1 | M14: =M17+0.02 -> 0.1 | N14: =N17+0.02 -> 0.1 | O14: =O17+0.02 -> 0.1 | ... Q14: =Q17+0.02 -> 0.1
B16: Base case
B17: Total Energy and Other | D17: =D7/C7-1 -> 0.5327907 | E17: =E7/D7-1 -> 0.51722045 | F17: =F7/E7-1 -> 0.4354 | G17: =G7/F7-1 -> 0.43653337 | H17: 0.4 | I17: 0.3 | J17: 0.2 | K17: 0.08 | L17: 0.08 | M17: 0.08 | N17: 0.08 | O17: 0.08 | P17: 0.08 | Q17: 0.08
B19: Worst case
B20: Total Energy and Other | H20: =H17-0.02 -> 0.38 | I20: =I17-0.02 -> 0.28 | J20: =J17-0.02 -> 0.18 | K20: =K17-0.02 -> 0.06 | L20: =L17-0.02 -> 0.06 | M20: =M17-0.02 -> 0.06 | N20: =N17-0.02 -> 0.06 | O20: =O17-0.02 -> 0.06 | ... Q20: =Q17-0.02 -> 0.06

Sheet GP Energy & Other
B1: Gross Profit Energy & Other
C3: Tesla GP% Energy and Other (in mln $)
B4: ($ in million) | C4: 2020 Act | D4: 2021 Act | E4: 2022 Act | F4: 2023 Act | G4: 2024 Act | H4: 2025 Fcst | I4: 2026 Fcst | J4: 2027 Fcst | K4: 2028 Fcst | L4: 2029 Fcst | M4: 2030 Fcst | N4: 2031 Fcst | O4: 2032 Fcst | P4: 2033 Fcst | Q4: 2034 Fcst
B5: Energy generation and storage | C5: =('P&L Input'!C5+'P&L Input'!C9)/1000 -> 18 | D5: =('P&L Input'!D5+'P&L Input'!D9)/1000 -> -129 | E5: =('P&L Input'!E5+'P&L Input'!E9)/1000 -> 288 | F5: =('P&L Input'!F5+'P&L Input'!F9)/1000 -> 1141 | G5: =('P&L Input'!G5+'P&L Input'!G9)/1000 -> 2640 | H5: n.a. | I5: n.a. | J5: n.a. | K5: n.a. | L5: n.a. | M5: n.a. | N5: n.a. | O5: n.a. | P5: n.a. | Q5: n.a.
B6: Services and other | C6: =('P&L Input'!C6+'P&L Input'!C10)/1000 -> -365 | D6: =('P&L Input'!D6+'P&L Input'!D10)/1000 -> -104 | E6: =('P&L Input'!E6+'P&L Input'!E10)/1000 -> 211 | F6: =('P&L Input'!F6+'P&L Input'!F10)/1000 -> 489 | G6: =('P&L Input'!G6+'P&L Input'!G10)/1000 -> 613 | H6: n.a. | I6: n.a. | J6: n.a. | K6: n.a. | L6: n.a. | M6: n.a. | N6: n.a. | O6: n.a. | P6: n.a. | Q6: n.a.
B7: Total Energy and Other | C7: =SUM(C5:C6) -> -347 | D7: =SUM(D5:D6) -> -233 | E7: =SUM(E5:E6) -> 499 | F7: =SUM(F5:F6) -> 1630 | G7: =SUM(G5:G6) -> 3253 | H7: ='Revenue Energy & Other'!H7*'GP Energy & Other'!H11 -> 5856.08 | I7: ='Revenue Energy & Other'!I7*'GP Energy & Other'!I11 -> 7730.0256 | J7: ='Revenue Energy & Other'!J7*'GP Energy & Other'!J11 -> 9430.6312 | K7: ='Revenue Energy & Other'!K7*'GP Energy & Other'!K11 -> 10373.694 | L7: ='Revenue Energy & Other'!L7*'GP Energy & Other'!L11 -> 11411.064 | M7: ='Revenue Energy & Other'!M7*'GP Energy & Other'!M11 -> 12552.17 | N7: ='Revenue Energy & Other'!N7*'GP Energy & Other'!N11 -> 13807.387 | O7: ='Revenue Energy & Other'!O7*'GP Energy & Other'!O11 -> 15188.126 | ... Q7: ='Revenue Energy & Other'!Q7*'GP Energy & Other'!Q11 -> 18377.632
B10: Selected case
B11: Total Energy and Other | H11: =CHOOSE(Drivers!$C$3,'GP Energy & Other'!H15,'GP Energy & Other'!H18,'GP Energy & Other'!H21) -> 0.2 | I11: =CHOOSE(Drivers!$C$3,'GP Energy & Other'!I15,'GP Energy & Other'!I18,'GP Energy & Other'!I21) -> 0.2 | J11: =CHOOSE(Drivers!$C$3,'GP Energy & Other'!J15,'GP Energy & Other'!J18,'GP Energy & Other'!J21) -> 0.2 | K11: =CHOOSE(Drivers!$C$3,'GP Energy & Other'!K15,'GP Energy & Other'!K18,'GP Energy & Other'!K21) -> 0.2 | L11: =CHOOSE(Drivers!$C$3,'GP Energy & Other'!L15,'GP Energy & Other'!L18,'GP Energy & Other'!L21) -> 0.2 | M11: =CHOOSE(Drivers!$C$3,'GP Energy & Other'!M15,'GP Energy & Other'!M18,'GP Energy & Other'!M21) -> 0.2 | N11: =CHOOSE(Drivers!$C$3,'GP Energy & Other'!N15,'GP Energy & Other'!N18,'GP Energy & Other'!N21) -> 0.2 | O11: =CHOOSE(Drivers!$C$3,'GP Energy & Other'!O15,'GP Energy & Other'!O18,'GP Energy & Other'!O21) -> 0.2 | ... Q11: =CHOOSE(Drivers!$C$3,'GP Energy & Other'!Q15,'GP Energy & Other'!Q18,'GP Energy & Other'!Q21) -> 0.2
B13: GP%
B14: Best case
B15: Total Energy and Other | H15: =H18+0.02 -> 0.2 | I15: =I18+0.02 -> 0.2 | J15: =J18+0.02 -> 0.2 | K15: =K18+0.02 -> 0.2 | L15: =L18+0.02 -> 0.2 | M15: =M18+0.02 -> 0.2 | N15: =N18+0.02 -> 0.2 | O15: =O18+0.02 -> 0.2 | ... Q15: =Q18+0.02 -> 0.2
B17: Base case
B18: Total Energy and Other | C18: =C7/'Revenue Energy & Other'!C7 -> -0.080697674 | D18: =D7/'Revenue Energy & Other'!D7 -> -0.035351237 | E18: =E7/'Revenue Energy & Other'!E7 -> 0.0499 | F18: =F7/'Revenue Energy & Other'!F7 -> 0.1135572 | G18: =G7/'Revenue Energy & Other'!G7 -> 0.15775946 | H18: 0.18 | I18: 0.18 | J18: 0.18 | K18: 0.18 | L18: 0.18 | M18: 0.18 | N18: 0.18 | O18: 0.18 | P18: 0.18 | Q18: 0.18
B20: Worst case
B21: Total Energy and Other | H21: =H18-0.02 -> 0.16 | I21: =I18-0.02 -> 0.16 | J21: =J18-0.02 -> 0.16 | K21: =K18-0.02 -> 0.16 | L21: =L18-0.02 -> 0.16 | M21: =M18-0.02 -> 0.16 | N21: =N18-0.02 -> 0.16 | O21: =O18-0.02 -> 0.16 | ... Q21: =Q18-0.02 -> 0.16

Sheet Cost of sales Energy & Other
B1: Cost of sales Energy & Other
C3: Tesla Cost of sales Energy & Other (in mln $)
B4: ($ in million) | C4: 2020 Act | D4: 2021 Act | E4: 2022 Act | F4: 2023 Act | G4: 2024 Act | H4: 2025 Fcst | I4: 2026 Fcst | J4: 2027 Fcst | K4: 2028 Fcst | L4: 2029 Fcst | M4: 2030 Fcst | N4: 2031 Fcst | O4: 2032 Fcst | P4: 2033 Fcst | Q4: 2034 Fcst
B5: Energy generation and storage | C5: =-('Revenue Energy & Other'!C5-'GP Energy & Other'!C5) -> -1976 | D5: =-('Revenue Energy & Other'!D5-'GP Energy & Other'!D5) -> -2918 | E5: =-('Revenue Energy & Other'!E5-'GP Energy & Other'!E5) -> -3621 | F5: =-('Revenue Energy & Other'!F5-'GP Energy & Other'!F5) -> -4894 | G5: =-('Revenue Energy & Other'!G5-'GP Energy & Other'!G5) -> -7446 | H5: n.a. | I5: n.a. | J5: n.a. | K5: n.a. | L5: n.a. | M5: n.a. | N5: n.a. | O5: n.a. | P5: n.a. | Q5: n.a.
B6: Services and other | C6: =-('Revenue Energy & Other'!C6-'GP Energy & Other'!C6) -> -2671 | D6: =-('Revenue Energy & Other'!D6-'GP Energy & Other'!D6) -> -3906 | E6: =-('Revenue Energy & Other'!E6-'GP Energy & Other'!E6) -> -5880 | F6: =-('Revenue Energy & Other'!F6-'GP Energy & Other'!F6) -> -7830 | G6: =-('Revenue Energy & Other'!G6-'GP Energy & Other'!G6) -> -9921 | H6: n.a. | I6: n.a. | J6: n.a. | K6: n.a. | L6: n.a. | M6: n.a. | N6: n.a. | O6: n.a. | P6: n.a. | Q6: n.a.
B7: Total Energy and Other | C7: =SUM(C5:C6) -> -4647 | D7: =SUM(D5:D6) -> -6824 | E7: =SUM(E5:E6) -> -9501 | F7: =SUM(F5:F6) -> -12724 | G7: =SUM(G5:G6) -> -17367 | H7: =-('Revenue Energy & Other'!H7-'GP Energy & Other'!H7) -> -23424.32 | I7: =-('Revenue Energy & Other'!I7-'GP Energy & Other'!I7) -> -30920.102 | J7: =-('Revenue Energy & Other'!J7-'GP Energy & Other'!J7) -> -37722.525 | K7: =-('Revenue Energy & Other'!K7-'GP Energy & Other'!K7) -> -41494.777 | L7: =-('Revenue Energy & Other'!L7-'GP Energy & Other'!L7) -> -45644.255 | M7: =-('Revenue Energy & Other'!M7-'GP Energy & Other'!M7) -> -50208.681 | N7: =-('Revenue Energy & Other'!N7-'GP Energy & Other'!N7) -> -55229.549 | O7: =-('Revenue Energy & Other'!O7-'GP Energy & Other'!O7) -> -60752.504 | ... Q7: =-('Revenue Energy & Other'!Q7-'GP Energy & Other'!Q7) -> -73510.529

Sheet Operating expenses
B14: Operating expenses

Sheet Opex comparables
B1: Opex comparables
B3: Comparables - 2024
B6: Company | C6: Average | D6: Adj. Average
B7: GM | C7: 0.152 | D7: =C7 -> 0.152
B8: Ford | C8: 0.13234766 | D8: =C8 -> 0.13234766
B9: Fiat Chrysler | C9: 0.093051845 | D9: =C9 -> 0.093051845
B10: BMW | C10: 0.099485177 | D10: =C10 -> 0.099485177
B11: Volkswagen | C11: 0.11 | D11: =C11 -> 0.11
B12: Jaguar | C12: 0.37065334
B13: Porsche | C13: 0.30660065
B14: Ferrari | C14: 0.2767445
B15: Scania | C15: 0.15 | D15: =C15 -> 0.15
B16: MAN | C16: 0.15 | D16: =C16 -> 0.15
B17: Paccar | C17: 0.03685738
B18: Average | C18: =AVERAGE(C7:C17) -> 0.17070369 | D18: =AVERAGE(D7:D17) -> 0.12669781

Sheet Opex
B1: Opex
C3: Tesla Opex (in mln $)
B4: ($ in million) | C4: 2020 Act | D4: 2021 Act | E4: 2022 Act | F4: 2023 Act | G4: 2024 Act | H4: 2025 Fcst | I4: 2026 Fcst | J4: 2027 Fcst | K4: 2028 Fcst | L4: 2029 Fcst | M4: 2030 Fcst | N4: 2031 Fcst | O4: 2032 Fcst | P4: 2033 Fcst | Q4: 2034 Fcst
B5: Revenues | C5: ='Revenue Energy & Other'!C7+'Revenue automotive'!C7 -> 31535.956 | D5: ='Revenue Energy & Other'!D7+'Revenue automotive'!D7 -> 53823.276 | E5: ='Revenue Energy & Other'!E7+'Revenue automotive'!E7 -> 81461.95 | F5: ='Revenue Energy & Other'!F7+'Revenue automotive'!F7 -> 96772.952 | G5: ='Revenue Energy & Other'!G7+'Revenue automotive'!G7 -> 97689.601 | H5: ='Revenue Energy & Other'!H7+'Revenue automotive'!H7 -> 107718.96 | I5: ='Revenue Energy & Other'!I7+'Revenue automotive'!I7 -> 121010.61 | J5: ='Revenue Energy & Other'!J7+'Revenue automotive'!J7 -> 133631.67 | ... Q5: ='Revenue Energy & Other'!Q7+'Revenue automotive'!Q7 -> 213572.11
B6: Opex as a % of revenues | C6: =C7/C5 -> -0.1470068 | D6: =D7/D5 -> -0.13159734 | E6: =E7/E5 -> -0.088347996 | F6: =F7/F5 -> -0.090614163 | G6: =G7/G5 -> -0.10619349 | H6: =H10 -> -0.10669781 | I6: =I10 -> -0.10669781 | J6: =J10 -> -0.10669781 | K6: =K10 -> -0.10669781 | L6: =L10 -> -0.10669781 | M6: =M10 -> -0.10669781 | N6: =N10 -> -0.10669781 | O6: =O10 -> -0.10669781 | ... Q6: =Q10 -> -0.10669781
B7: Opex | C7: =SUM('P&L Input'!C12:C14)/1000 -> -4636 | D7: =SUM('P&L Input'!D12:D14)/1000 -> -7083 | E7: =SUM('P&L Input'!E12:E14)/1000 -> -7197 | F7: =SUM('P&L Input'!F12:F14)/1000 -> -8769 | G7: =SUM('P&L Input'!G12:G14)/1000 -> -10374 | H7: =H5*H6 -> -11493.377 | I7: =I5*I6 -> -12911.568 | J7: =J5*J6 -> -14258.206 | K7: =K5*K6 -> -15222.674 | L7: =L5*L6 -> -16260.52 | M7: =M5*M6 -> -17377.93 | N7: =N5*N6 -> -18581.649 | O7: =O5*O6 -> -19879.035 | ... Q7: =Q5*Q6 -> -22787.677
B9: Selected case
B10: Opex as a % of revenue | H10: =CHOOSE(Drivers!$C$3,Opex!H14,Opex!H17,Opex!H20) -> -0.10669781 | I10: =CHOOSE(Drivers!$C$3,Opex!I14,Opex!I17,Opex!I20) -> -0.10669781 | J10: =CHOOSE(Drivers!$C$3,Opex!J14,Opex!J17,Opex!J20) -> -0.10669781 | K10: =CHOOSE(Drivers!$C$3,Opex!K14,Opex!K17,Opex!K20) -> -0.10669781 | L10: =CHOOSE(Drivers!$C$3,Opex!L14,Opex!L17,Opex!L20) -> -0.10669781 | M10: =CHOOSE(Drivers!$C$3,Opex!M14,Opex!M17,Opex!M20) -> -0.10669781 | N10: =CHOOSE(Drivers!$C$3,Opex!N14,Opex!N17,Opex!N20) -> -0.10669781 | O10: =CHOOSE(Drivers!$C$3,Opex!O14,Opex!O17,Opex!O20) -> -0.10669781 | ... Q10: =CHOOSE(Drivers!$C$3,Opex!Q14,Opex!Q17,Opex!Q20) -> -0.10669781
B12: Opex %
B13: Best case
B14: Opex as a % of revenue | H14: =H17+2% -> -0.10669781 | I14: =I17+2% -> -0.10669781 | J14: =J17+2% -> -0.10669781 | K14: =K17+2% -> -0.10669781 | L14: =L17+2% -> -0.10669781 | M14: =M17+2% -> -0.10669781 | N14: =N17+2% -> -0.10669781 | O14: =O17+2% -> -0.10669781 | ... Q14: =Q17+2% -> -0.10669781
B16: Base case
B17: Opex as a % of revenue | H17: =-'Opex comparables'!$D$18 -> -0.12669781 | I17: =-'Opex comparables'!$D$18 -> -0.12669781 | J17: =-'Opex comparables'!$D$18 -> -0.12669781 | K17: =-'Opex comparables'!$D$18 -> -0.12669781 | L17: =-'Opex comparables'!$D$18 -> -0.12669781 | M17: =-'Opex comparables'!$D$18 -> -0.12669781 | N17: =-'Opex comparables'!$D$18 -> -0.12669781 | O17: =-'Opex comparables'!$D$18 -> -0.12669781 | ... Q17: =-'Opex comparables'!$D$18 -> -0.12669781
B19: Worst case
B20: Opex as a % of revenue | H20: =H17-2% -> -0.14669781 | I20: =I17-2% -> -0.14669781 | J20: =J17-2% -> -0.14669781 | K20: =K17-2% -> -0.14669781 | L20: =L17-2% -> -0.14669781 | M20: =M17-2% -> -0.14669781 | N20: =N17-2% -> -0.14669781 | O20: =O17-2% -> -0.14669781 | ... Q20: =Q17-2% -> -0.14669781

Sheet Balance Sheet -->
B14: Balance Sheet -->

Sheet PP&E -->
B14: Property, Plant & Equipment

Sheet PP&E
B1: Fixed asset roll forward
B3: ="Selected case:"&CHOOSE(C3," as a % of PPE"," as a % of revenue") -> Selected case: as a % of PPE | C3: 1
C5: Tesla PP&E (in mln $)
B6: ($ in million) | C6: 31Dec2020 Act | D6: 31Dec2021 Act | E6: 31Dec2022 Act | F6: 31Dec2023 Act | G6: 31Dec2024 Act | H6: 31Dec2025 Fcst | I6: 31Dec2026 Fcst | J6: 31Dec2027 Fcst | K6: 31Dec2028 Fcst | L6: 31Dec2029 Fcst | M6: 31Dec2030 Fcst | N6: 31Dec2031 Fcst | O6: 31Dec2032 Fcst | P6: 31Dec2033 Fcst | Q6: 31Dec2034 Fcst
B7: Beginning PP&E | C7: 10396 | D7: =C10 -> 12747 | E7: =D10 -> 18884 | F7: =E10 -> 23548 | G7: =F10 -> 29725 | H7: =G10 -> 35836 | I7: =H10 -> 46989.286 | J7: =I10 -> 61186.648 | K7: =J10 -> 79285.265 | ... Q7: =P10 -> 358212.24
B8: Capex | C8: =C10-C7-C9 -> 4505 | D8: =D10-D7-D9 -> 8519 | E8: =E10-E7-E9 -> 7232 | F8: =F10-F7-F9 -> 8977 | G8: =G10-G7-G9 -> 9345 | H8: =CHOOSE($C$3,H32*H7,H33*Opex!H5) -> 6881.5324 | I8: =CHOOSE($C$3,I32*I7,I33*Opex!I5) -> 9023.2807 | J8: =CHOOSE($C$3,J32*J7,J33*Opex!J5) -> 11749.579 | K8: =CHOOSE($C$3,K32*K7,K33*Opex!K5) -> 15225.028 | L8: =CHOOSE($C$3,L32*L7,L33*Opex!L5) -> 19660.228 | M8: =CHOOSE($C$3,M32*M7,M33*Opex!M5) -> 25324.644 | N8: =CHOOSE($C$3,N32*N7,N33*Opex!N5) -> 32563.094 | O8: =CHOOSE($C$3,O32*O7,O33*Opex!O5) -> 41816.837 | ... Q8: =CHOOSE($C$3,Q32*Q7,Q33*Opex!Q5) -> 68786.949
B9: D&A | C9: -2154 | D9: -2382 | E9: -2568 | F9: -2800 | G9: -3234 | H9: =H28 -> 4271.7532 | I9: =I28 -> 5174.0813 | J9: =J28 -> 6349.0392 | K9: =K28 -> 7871.542 | L9: =L28 -> 9837.5648 | M9: =M28 -> 12370.029 | N9: =N28 -> 15626.339 | O9: =O28 -> 19808.022 | ... Q9: =Q28 -> 32051.774
B10: Ending PP&E | C10: ='Balance Sheet Input'!C12/1000 -> 12747 | D10: ='Balance Sheet Input'!D12/1000 -> 18884 | E10: ='Balance Sheet Input'!E12/1000 -> 23548 | F10: ='Balance Sheet Input'!F12/1000 -> 29725 | G10: ='Balance Sheet Input'!G12/1000 -> 35836 | H10: =SUM(H7:H9) -> 46989.286 | I10: =SUM(I7:I9) -> 61186.648 | J10: =SUM(J7:J9) -> 79285.265 | K10: =SUM(K7:K9) -> 102381.84 | L10: =SUM(L7:L9) -> 131879.63 | M10: =SUM(M7:M9) -> 169574.3 | N10: =SUM(N7:N9) -> 217763.73 | O10: =SUM(O7:O9) -> 279388.59 | ... Q10: =SUM(Q7:Q9) -> 459050.96
B12: Useful life Capex (Years) | C12: 10
B13: Useful life historical assets (Years) | C13: 10
C15: Tesla D&A (in mln $)
B16: ($ in million) | C16: 31Dec2015 Act | D16: 31Dec2016 Act | E16: 31Dec2017 Act | F16: 31Dec2018 Act | G16: 31Dec2019 Act | H16: 31Dec2020 Fcst | I16: 31Dec2021 Fcst | J16: 31Dec2022 Fcst | K16: 31Dec2023 Fcst | L16: 31Dec2024 Fcst | M16: 31Dec2025 Fcst | N16: 31Dec2026 Fcst | O16: 31Dec2027 Fcst | P16: 31Dec2028 Fcst | Q16: 31Dec2029 Fcst
H17: =$H$7/$C$13 -> 3583.6 | I17: =$H$7/$C$13 -> 3583.6 | J17: =$H$7/$C$13 -> 3583.6 | K17: =$H$7/$C$13 -> 3583.6 | L17: =$H$7/$C$13 -> 3583.6 | M17: =$H$7/$C$13 -> 3583.6 | N17: =$H$7/$C$13 -> 3583.6 | O17: =$H$7/$C$13 -> 3583.6 | ... Q17: =$H$7/$C$13 -> 3583.6
H18: =$H$8/$C$12 -> 688.15324 | I18: =$H$8/$C$12 -> 688.15324 | J18: =$H$8/$C$12 -> 688.15324 | K18: =$H$8/$C$12 -> 688.15324 | L18: =$H$8/$C$12 -> 688.15324 | M18: =$H$8/$C$12 -> 688.15324 | N18: =$H$8/$C$12 -> 688.15324 | O18: =$H$8/$C$12 -> 688.15324 | ... Q18: =$H$8/$C$12 -> 688.15324
I19: =$I$8/$C$12 -> 902.32807 | J19: =$I$8/$C$12 -> 902.32807 | K19: =$I$8/$C$12 -> 902.32807 | L19: =$I$8/$C$12 -> 902.32807 | M19: =$I$8/$C$12 -> 902.32807 | N19: =$I$8/$C$12 -> 902.32807 | O19: =$I$8/$C$12 -> 902.32807 | P19: =$I$8/$C$12 -> 902.32807 | Q19: =$I$8/$C$12 -> 902.32807
J20: =$J$8/$C$12 -> 1174.9579 | K20: =$J$8/$C$12 -> 1174.9579 | L20: =$J$8/$C$12 -> 1174.9579 | M20: =$J$8/$C$12 -> 1174.9579 | N20: =$J$8/$C$12 -> 1174.9579 | O20: =$J$8/$C$12 -> 1174.9579 | P20: =$J$8/$C$12 -> 1174.9579 | Q20: =$J$8/$C$12 -> 1174.9579
K21: =$K$8/$C$12 -> 1522.5028 | L21: =$K$8/$C$12 -> 1522.5028 | M21: =$K$8/$C$12 -> 1522.5028 | N21: =$K$8/$C$12 -> 1522.5028 | O21: =$K$8/$C$12 -> 1522.5028 | P21: =$K$8/$C$12 -> 1522.5028 | Q21: =$K$8/$C$12 -> 1522.5028
L22: =$L$8/$C$12 -> 1966.0228 | M22: =$L$8/$C$12 -> 1966.0228 | N22: =$L$8/$C$12 -> 1966.0228 | O22: =$L$8/$C$12 -> 1966.0228 | P22: =$L$8/$C$12 -> 1966.0228 | Q22: =$L$8/$C$12 -> 1966.0228
M23: =$M$8/$C$12 -> 2532.4644 | N23: =$M$8/$C$12 -> 2532.4644 | O23: =$M$8/$C$12 -> 2532.4644 | P23: =$M$8/$C$12 -> 2532.4644 | Q23: =$M$8/$C$12 -> 2532.4644
N24: =$N$8/$C$12 -> 3256.3094 | O24: =$N$8/$C$12 -> 3256.3094 | P24: =$N$8/$C$12 -> 3256.3094 | Q24: =$N$8/$C$12 -> 3256.3094
O25: =$O$8/$C$12 -> 4181.6837 | P25: =$O$8/$C$12 -> 4181.6837 | Q25: =$O$8/$C$12 -> 4181.6837
P26: =$P$8/$C$12 -> 5365.0565 | Q26: =$P$8/$C$12 -> 5365.0565
Q27: =Q8/C12 -> 6878.6949
B28: Total D&A | C28: =SUM(C17:C27) -> 0 | D28: =SUM(D17:D27) -> 0 | E28: =SUM(E17:E27) -> 0 | F28: =SUM(F17:F27) -> 0 | G28: =SUM(G17:G27) -> 0 | H28: =SUM(H17:H27) -> 4271.7532 | I28: =SUM(I17:I27) -> 5174.0813 | J28: =SUM(J17:J27) -> 6349.0392 | ... Q28: =SUM(Q17:Q27) -> 32051.774
B31: Selected case
B32: Capex as a % of PP&E | H32: =CHOOSE(Drivers!$C$3,'PP&E'!H36,'PP&E'!H39,'PP&E'!H42) -> 0.19202847 | I32: =CHOOSE(Drivers!$C$3,'PP&E'!I36,'PP&E'!I39,'PP&E'!I42) -> 0.19202847 | J32: =CHOOSE(Drivers!$C$3,'PP&E'!J36,'PP&E'!J39,'PP&E'!J42) -> 0.19202847 | K32: =CHOOSE(Drivers!$C$3,'PP&E'!K36,'PP&E'!K39,'PP&E'!K42) -> 0.19202847 | L32: =CHOOSE(Drivers!$C$3,'PP&E'!L36,'PP&E'!L39,'PP&E'!L42) -> 0.19202847 | M32: =CHOOSE(Drivers!$C$3,'PP&E'!M36,'PP&E'!M39,'PP&E'!M42) -> 0.19202847 | N32: =CHOOSE(Drivers!$C$3,'PP&E'!N36,'PP&E'!N39,'PP&E'!N42) -> 0.19202847 | O32: =CHOOSE(Drivers!$C$3,'PP&E'!O36,'PP&E'!O39,'PP&E'!O42) -> 0.19202847 | ... Q32: =CHOOSE(Drivers!$C$3,'PP&E'!Q36,'PP&E'!Q39,'PP&E'!Q42) -> 0.19202847
B33: Capex as a % of revenue | H33: =CHOOSE(Drivers!$C$3,'PP&E'!H37,'PP&E'!H40,'PP&E'!H43) -> 0.034053331 | I33: =CHOOSE(Drivers!$C$3,'PP&E'!I37,'PP&E'!I40,'PP&E'!I43) -> 0.034053331 | J33: =CHOOSE(Drivers!$C$3,'PP&E'!J37,'PP&E'!J40,'PP&E'!J43) -> 0.034053331 | K33: =CHOOSE(Drivers!$C$3,'PP&E'!K37,'PP&E'!K40,'PP&E'!K43) -> 0.034053331 | L33: =CHOOSE(Drivers!$C$3,'PP&E'!L37,'PP&E'!L40,'PP&E'!L43) -> 0.034053331 | M33: =CHOOSE(Drivers!$C$3,'PP&E'!M37,'PP&E'!M40,'PP&E'!M43) -> 0.034053331 | N33: =CHOOSE(Drivers!$C$3,'PP&E'!N37,'PP&E'!N40,'PP&E'!N43) -> 0.034053331 | O33: =CHOOSE(Drivers!$C$3,'PP&E'!O37,'PP&E'!O40,'PP&E'!O43) -> 0.034053331 | ... Q33: =CHOOSE(Drivers!$C$3,'PP&E'!Q37,'PP&E'!Q40,'PP&E'!Q43) -> 0.094053331
B34: Capex %
B35: Best case
B36: Capex as a % of PP&E | H36: =H39-5% -> 0.19202847 | I36: =I39-5% -> 0.19202847 | J36: =J39-5% -> 0.19202847 | K36: =K39-5% -> 0.19202847 | L36: =L39-5% -> 0.19202847 | M36: =M39-5% -> 0.19202847 | N36: =N39-5% -> 0.19202847 | O36: =O39-5% -> 0.19202847 | ... Q36: =Q39-5% -> 0.19202847
B37: =B33 -> Capex as a % of revenue | H37: =H40-3% -> 0.034053331 | I37: =I40-3% -> 0.034053331 | J37: =J40-3% -> 0.034053331 | K37: =K40-3% -> 0.034053331 | L37: =L40-3% -> 0.034053331 | M37: =M40-3% -> 0.034053331 | N37: =N40-3% -> 0.034053331 | O37: =O40-3% -> 0.034053331 | P37: =P40-3% -> 0.034053331 | Q37: =Q40+3% -> 0.094053331
B38: Base case
B39: Capex as a % of PP&E | H39: =-'PP&E Comparables'!D16 -> 0.24202847 | I39: =H39 -> 0.24202847 | J39: =I39 -> 0.24202847 | K39: =J39 -> 0.24202847 | L39: =K39 -> 0.24202847 | M39: =L39 -> 0.24202847 | N39: =M39 -> 0.24202847 | O39: =N39 -> 0.24202847 | P39: =O39 -> 0.24202847 | Q39: =P39 -> 0.24202847
B40: =B33 -> Capex as a % of revenue | H40: =-'PP&E Comparables'!G16 -> 0.064053331 | I40: =H40 -> 0.064053331 | J40: =I40 -> 0.064053331 | K40: =J40 -> 0.064053331 | L40: =K40 -> 0.064053331 | M40: =L40 -> 0.064053331 | N40: =M40 -> 0.064053331 | O40: =N40 -> 0.064053331 | P40: =O40 -> 0.064053331 | Q40: =P40 -> 0.064053331
B41: Worst case
B42: Capex as a % of PP&E | H42: =H39+5% -> 0.29202847 | I42: =I39+5% -> 0.29202847 | J42: =J39+5% -> 0.29202847 | K42: =K39+5% -> 0.29202847 | L42: =L39+5% -> 0.29202847 | M42: =M39+5% -> 0.29202847 | N42: =N39+5% -> 0.29202847 | O42: =O39+5% -> 0.29202847 | ... Q42: =Q39+5% -> 0.29202847
B43: =B33 -> Capex as a % of revenue | H43: =H40+3% -> 0.094053331 | I43: =I40+3% -> 0.094053331 | J43: =J40+3% -> 0.094053331 | K43: =K40+3% -> 0.094053331 | L43: =L40+3% -> 0.094053331 | M43: =M40+3% -> 0.094053331 | N43: =N40+3% -> 0.094053331 | O43: =O40+3% -> 0.094053331 | P43: =P40+3% -> 0.094053331 | Q43: =Q40-3% -> 0.034053331

Sheet PP&E Comparables
B1: PP&E comparables
B3: Comparables - 2024
C5: CAPEX as a % of PP&E | F5: CAPEX as a % of revenues
B6: Company | C6: Average | D6: Adj. Average | F6: Average | G6: Adj. Average
B7: GM | C7: -0.19592258 | D7: =C7 -> -0.19592258 | F7: -0.055320358 | G7: =F7 -> -0.055320358
B8: Ford | C8: -0.21112278 | D8: =C8 -> -0.21112278 | F8: -0.048992944 | G8: =F8 -> -0.048992944
B9: Fiat Chrysler | C9: -0.29309983 | D9: =C9 -> -0.29309983 | F9: -0.077504691 | G9: =F9 -> -0.077504691
B10: BMW | C10: -0.29601301 | D10: =C10 -> -0.29601301 | F10: -0.073449532 | G10: =F10 -> -0.073449532
B11: Mercedes | C11: -0.19381849 | D11: =C11 -> -0.19381849 | F11: -0.041674144 | G11: =F11 -> -0.041674144
B12: Volkswagen | C12: -0.21511065 | D12: =C12 -> -0.21511065 | F12: -0.056326989 | G12: =F12 -> -0.056326989
B13: Jaguar | C13: -0.24491682 | D13: =C13 -> -0.24491682 | F13: -0.065664492 | G13: =F13 -> -0.065664492
B14: Ferrari | C14: -0.32922296 | D14: =C14 -> -0.32922296 | F14: -0.093493495 | G14: =F14 -> -0.093493495
B15: Paccar | C15: -0.19902913 | D15: =C15 -> -0.19902913 | F15: -0.023797678
B16: Average | C16: =AVERAGE(C7:C15) -> -0.24202847 | D16: =AVERAGE(D7:D15) -> -0.24202847 | F16: =AVERAGE(F7:F15) -> -0.05958048 | G16: =AVERAGE(G7:G15) -> -0.064053331
